Workbook

Sheet 概要
B2: 智能锁管理系统
B4: 数据库详细设计书
B6: 功能描述：
B8: 用于数据表设计详细说明内容包括： 1、目录：将文档按照功能分类，列出所有文档的名称，文档名称连接到对应表定义的sheet页，并做文档的作用做简要说明。 2、文档详细定义：一个sheet一个文档，对文档的字段、索引进行详细的定义。
B20: 版本号 | G20: 修订日期 | M20: 修订人 | T20: 修订说明
B21: 1 | G21: 44901 | M21: wzs

Sheet 目录
A1: 项目名称： | E1: 数据库详细设计书
B3: 目录 | E3: 表名 | F3: 说明 | G3: 版本 | H3: 完成状态 | AB3: 原表
E4: sl_person | F4: =sl_person!D1 -> 人员信息表 | H4: 完成
E5: sl_room | F5: =sl_room!D1 -> 机房信息表 | H5: 完成
E6: sl_area_type | F6: =sl_area_type!D1 -> 区域类型字典 | H6: 完成
E7: sl_lock | F7: =sl_lock!D1 -> 智能锁信息表 | H7: 完成
E8: sl_key | F8: =sl_key!D1 -> 智能钥匙信息表 | H8: 完成
E9: sl_key_controller | F9: =sl_key_controller!D1 -> 智能钥匙管理机信息表 | H9: 完成
E10: sl_lock_status_record | F10: =sl_lock_status_record!D1 -> 智能锁状态记录表 | H10: 完成
E11: sl_application | F11: =sl_application!D1 -> 智能锁开锁申请 | H11: 完成
E12: sl_key_authorization | F12: =sl_key_authorization!D1 -> 智能钥匙授权记录表 | H12: 完成
E13: sl_lock_authorization | F13: =sl_lock_authorization!D1 -> 智能锁远程开启记录表 | H13: 完成
E14: sl_lock_sl_lock_authorization | F14: =sl_lock_sl_lock_authorization!D1 -> 智远程开锁对应智能锁关联表 | H14: 完成
E15: sl_lock_authorization_sl_person | F15: =sl_lock_authorization_sl_person!D1 -> 智远程开锁对应施工人员关联表 | H15: 完成
E16: sl_application_sl_key_authoriza | F16: =sl_application_sl_key_authoriza!D1 -> 钥匙授权中对应开锁申请关联表 | H16: 完成
E17: sl_application_sl_lock | F17: =sl_application_sl_lock!D1 -> 开锁申请对应智能锁关联表 | H17: 完成
E18: sl_application_sl_person | F18: =sl_application_sl_person!D1 -> 开锁申请对应施工人员关联表 | H18: 完成
E19: sl_lock_hub | F19: =sl_lock_hub!D1 -> 智能锁网关信息表

Sheet sl_person
A1: 表名： | B1: sl_person | C1: 说明： | D1: 人员信息表 | F1: 版本 | H1: 1 | I1: ="create table "&B1&" (" -> create table sl_person ( | N1: 目录
A2: 字段 | B2: 类型 | C2: 长度 | D2: 主键 | E2: 是否为空 | F2: 默认值 | G2: 字段名称 | H2: 说明
A3: id | B3: varchar | C3: 20 | D3: Y | E3: NOT NULL | G3: 账号 | H3: 建议使用员工编号 | I3: =A3&" "&B3&"("&C3&") "&E3&" "&F3&"," -> id varchar(20) NOT NULL , | J3: ="{""field"":"""&A3&""",""name"":"""&G3&""",""dataType"":"""&B3&"""}," -> {"field":"id","name":"账号","dataType":"varchar"}, | K3: ="{""field"":"""&A3&""",""labelRegexp"":"""&G3&""",""excelRangeType"":""table""}," -> {"field":"id","labelRegexp":"账号","excelRangeType":"table"}, | L3: ="{""field"":"""&A3&""",""width"":150}," -> {"field":"id","width":150},
A4: name | B4: varchar | C4: 20 | D4: N | E4: NOT NULL | G4: 姓名 | I4: =A4&" "&B4&"("&C4&") "&E4&" "&F4&"," -> name varchar(20) NOT NULL , | J4: ="{""field"":"""&A4&""",""name"":"""&G4&""",""dataType"":"""&B4&"""}," -> {"field":"name","name":"姓名","dataType":"varchar"}, | K4: ="{""field"":"""&A4&""",""labelRegexp"":"""&G4&""",""excelRangeType"":""table""}," -> {"field":"name","labelRegexp":"姓名","excelRangeType":"table"}, | L4: ="{""field"":"""&A4&""",""width"":150}," -> {"field":"name","width":150},
A5: gender | B5: varchar | C5: 2 | D5: N | E5: NULL | G5: 性别 | H5: 男 女 | I5: =A5&" "&B5&"("&C5&") "&E5&" "&F5&"," -> gender varchar(2) NULL , | J5: ="{""field"":"""&A5&""",""name"":"""&G5&""",""dataType"":"""&B5&"""}," -> {"field":"gender","name":"性别","dataType":"varchar"}, | K5: ="{""field"":"""&A5&""",""labelRegexp"":"""&G5&""",""excelRangeType"":""table""}," -> {"field":"gender","labelRegexp":"性别","excelRangeType":"table"}, | L5: ="{""field"":"""&A5&""",""width"":150}," -> {"field":"gender","width":150},
A6: company | B6: varchar | C6: 255 | D6: N | E6: NULL | G6: 单位 | I6: =A6&" "&B6&"("&C6&") "&E6&" "&F6&"," -> company varchar(255) NULL , | J6: ="{""field"":"""&A6&""",""name"":"""&G6&""",""dataType"":"""&B6&"""}," -> {"field":"company","name":"单位","dataType":"varchar"}, | K6: ="{""field"":"""&A6&""",""labelRegexp"":"""&G6&""",""excelRangeType"":""table""}," -> {"field":"company","labelRegexp":"单位","excelRangeType":"table"}, | L6: ="{""field"":"""&A6&""",""width"":150}," -> {"field":"company","width":150},
A7: department | B7: varchar | C7: 255 | D7: N | E7: NULL | G7: 部门 | I7: =A7&" "&B7&"("&C7&") "&E7&" "&F7&"," -> department varchar(255) NULL , | J7: ="{""field"":"""&A7&""",""name"":"""&G7&""",""dataType"":"""&B7&"""}," -> {"field":"department","name":"部门","dataType":"varchar"}, | K7: ="{""field"":"""&A7&""",""labelRegexp"":"""&G7&""",""excelRangeType"":""table""}," -> {"field":"department","labelRegexp":"部门","excelRangeType":"table"}, | L7: ="{""field"":"""&A7&""",""width"":150}," -> {"field":"department","width":150},
A8: position | B8: varchar | C8: 255 | D8: N | E8: NULL | G8: 职位 | I8: =A8&" "&B8&"("&C8&") "&E8&" "&F8&"," -> position varchar(255) NULL , | J8: ="{""field"":"""&A8&""",""name"":"""&G8&""",""dataType"":"""&B8&"""}," -> {"field":"position","name":"职位","dataType":"varchar"}, | K8: ="{""field"":"""&A8&""",""labelRegexp"":"""&G8&""",""excelRangeType"":""table""}," -> {"field":"position","labelRegexp":"职位","excelRangeType":"table"}, | L8: ="{""field"":"""&A8&""",""width"":150}," -> {"field":"position","width":150},
A9: phone | B9: varchar | C9: 25 | D9: N | E9: NULL | G9: 联系电话 | I9: =A9&" "&B9&"("&C9&") "&E9&" "&F9&"," -> phone varchar(25) NULL , | J9: ="{""field"":"""&A9&""",""name"":"""&G9&""",""dataType"":"""&B9&"""}," -> {"field":"phone","name":"联系电话","dataType":"varchar"}, | K9: ="{""field"":"""&A9&""",""labelRegexp"":"""&G9&""",""excelRangeType"":""table""}," -> {"field":"phone","labelRegexp":"联系电话","excelRangeType":"table"}, | L9: ="{""field"":"""&A9&""",""width"":150}," -> {"field":"phone","width":150},
A10: email | B10: varchar | C10: 255 | D10: N | E10: NULL | G10: 邮箱 | I10: =A10&" "&B10&"("&C10&") "&E10&" "&F10&"," -> email varchar(255) NULL , | J10: ="{""field"":"""&A10&""",""name"":"""&G10&""",""dataType"":"""&B10&"""}," -> {"field":"email","name":"邮箱","dataType":"varchar"}, | K10: ="{""field"":"""&A10&""",""labelRegexp"":"""&G10&""",""excelRangeType"":""table""}," -> {"field":"email","labelRegexp":"邮箱","excelRangeType":"table"}, | L10: ="{""field"":"""&A10&""",""width"":150}," -> {"field":"email","width":150},
A11: import_file_name | B11: varchar | C11: 260 | D11: N | E11: NULL | G11: 导入文件名称 | I11: =A11&" "&B11&"("&C11&") "&E11&" "&F11&"," -> import_file_name varchar(260) NULL , | J11: ="{""field"":"""&A11&""",""name"":"""&G11&""",""dataType"":"""&B11&"""}," -> {"field":"import_file_name","name":"导入文件名称","dataType":"varchar"}, | K11: ="{""field"":"""&A11&""",""labelRegexp"":"""&G11&""",""excelRangeType"":""table""}," -> {"field":"import_file_name","labelRegexp":"导入文件名称","excelRangeType":"table"}, | L11: ="{""field"":"""&A11&""",""width"":150}," -> {"field":"import_file_name","width":150},
A12: import_batch_number | B12: varchar | C12: 25 | D12: N | E12: NULL | G12: 导入批次 | I12: =A12&" "&B12&"("&C12&") "&E12&" "&F12&"," -> import_batch_number varchar(25) NULL , | J12: ="{""field"":"""&A12&""",""name"":"""&G12&""",""dataType"":"""&B12&"""}," -> {"field":"import_batch_number","name":"导入批次","dataType":"varchar"}, | L12: ="{""field"":"""&A12&""",""width"":150}," -> {"field":"import_batch_number","width":150},
A13: create_time | B13: datetime | C13: 0 | D13: N | E13: NOT NULL | G13: 记录创建时间 | H13: 记录创建时间 | I13: =A13&" "&B13&"("&C13&") "&E13&" "&F13&"," -> create_time datetime(0) NOT NULL , | J13: ="{""field"":"""&A13&""",""name"":"""&G13&""",""dataType"":"""&B13&"""}," -> {"field":"create_time","name":"记录创建时间","dataType":"datetime"}, | K13: ="{""field"":"""&A13&""",""labelRegexp"":"""&G13&""",""excelRangeType"":""table""}," -> {"field":"create_time","labelRegexp":"记录创建时间","excelRangeType":"table"}, | L13: ="{""field"":"""&A13&""",""width"":150}," -> {"field":"create_time","width":150},
A14: create_user | B14: varchar | C14: 25 | D14: N | E14: NOT NULL | G14: 记录创建人 | H14: 记录创建人 | I14: =A14&" "&B14&"("&C14&") "&E14&" "&F14&"," -> create_user varchar(25) NOT NULL , | J14: ="{""field"":"""&A14&""",""name"":"""&G14&""",""dataType"":"""&B14&"""}," -> {"field":"create_user","name":"记录创建人","dataType":"varchar"}, | K14: ="{""field"":"""&A14&""",""labelRegexp"":"""&G14&""",""excelRangeType"":""table""}," -> {"field":"create_user","labelRegexp":"记录创建人","excelRangeType":"table"}, | L14: ="{""field"":"""&A14&""",""width"":150}," -> {"field":"create_user","width":150},
A15: update_time | B15: datetime | C15: 0 | D15: N | E15: NOT NULL | G15: 记录更新时间 | H15: 记录更新时间 | I15: =A15&" "&B15&"("&C15&") "&E15&" "&F15&"," -> update_time datetime(0) NOT NULL , | J15: ="{""field"":"""&A15&""",""name"":"""&G15&""",""dataType"":"""&B15&"""}," -> {"field":"update_time","name":"记录更新时间","dataType":"datetime"}, | K15: ="{""field"":"""&A15&""",""labelRegexp"":"""&G15&""",""excelRangeType"":""table""}," -> {"field":"update_time","labelRegexp":"记录更新时间","excelRangeType":"table"}, | L15: ="{""field"":"""&A15&""",""width"":150}," -> {"field":"update_time","width":150},
A16: update_user | B16: varchar | C16: 25 | D16: N | E16: NOT NULL | G16: 记录更新人 | H16: 记录更新人 | I16: =A16&" "&B16&"("&C16&") "&E16&" "&F16&"," -> update_user varchar(25) NOT NULL , | J16: ="{""field"":"""&A16&""",""name"":"""&G16&""",""dataType"":"""&B16&"""}," -> {"field":"update_user","name":"记录更新人","dataType":"varchar"}, | K16: ="{""field"":"""&A16&""",""labelRegexp"":"""&G16&""",""excelRangeType"":""table""}," -> {"field":"update_user","labelRegexp":"记录更新人","excelRangeType":"table"}, | L16: ="{""field"":"""&A16&""",""width"":150}," -> {"field":"update_user","width":150},
A17: version | B17: int | C17: 11 | D17: N | E17: NOT NULL | F17: DEFAULT 0 | G17: 数据版本号 | H17: 数据版本号 | I17: =A17&" "&B17&"("&C17&") "&E17&" "&F17&"," -> version int(11) NOT NULL DEFAULT 0, | J17: ="{""field"":"""&A17&""",""name"":"""&G17&""",""dataType"":"""&B17&"""}," -> {"field":"version","name":"数据版本号","dataType":"int"}, | K17: ="{""field"":"""&A17&""",""labelRegexp"":"""&G17&""",""excelRangeType"":""table""}," -> {"field":"version","labelRegexp":"数据版本号","excelRangeType":"table"}, | L17: ="{""field"":"""&A17&""",""width"":150}," -> {"field":"version","width":150},
I18: ="PRIMARY KEY (`id`) USING BTREE)" -> PRIMARY KEY (`id`) USING BTREE)

Sheet sl_lock_authorization
A1: 表名： | B1: sl_lock_authorization | C1: 说明： | D1: 智能锁远程开启记录表 | F1: 版本 | H1: 1 | I1: ="create table "&B1&" (" -> create table sl_lock_authorization ( | N1: 目录
A2: 字段 | B2: 类型 | C2: 长度 | D2: 主键 | E2: 是否为空 | F2: 默认值 | G2: 字段名称 | H2: 说明
A3: id | B3: bigint | C3: 18 | D3: Y | E3: NOT NULL | G3: 编号 | H3: 自增ID | I3: =A3&" "&B3&"("&C3&") "&E3&" "&F3&"," -> id bigint(18) NOT NULL , | J3: ="{""field"":"""&A3&""",""name"":"""&G3&""",""dataType"":"""&B3&"""}," -> {"field":"id","name":"编号","dataType":"bigint"}, | K3: ="{""field"":"""&A3&""",""labelRegexp"":"""&G3&""",""excelRangeType"":""table""}," -> {"field":"id","labelRegexp":"编号","excelRangeType":"table"}, | L3: ="{""field"":"""&A3&""",""width"":150}," -> {"field":"id","width":150},
A4: locks | G4: 智能锁 | H4: 对应到智能锁表多对多关联 | J4: ="{""field"":"""&A4&""",""name"":"""&G4&""",""dataType"":"""&B4&"""}," -> {"field":"locks","name":"智能锁","dataType":""}, | K4: ="{""field"":"""&A4&""",""labelRegexp"":"""&G4&""",""excelRangeType"":""table""}," -> {"field":"locks","labelRegexp":"智能锁","excelRangeType":"table"}, | L4: ="{""field"":"""&A4&""",""width"":150}," -> {"field":"locks","width":150},
A5: operators | G5: 操作人 | H5: 多对多关联人员表
A6: close_delay | B6: varchar | C6: 3 | D6: N | E6: NOT NULL | F6: DEFAULT '010' | G6: 闭锁延迟 | H6: 010:10秒 030:30秒 060:60秒 | I6: =A6&" "&B6&"("&C6&") "&E6&" "&F6&"," -> close_delay varchar(3) NOT NULL DEFAULT '010', | J6: ="{""field"":"""&A6&""",""name"":"""&G6&""",""dataType"":"""&B6&"""}," -> {"field":"close_delay","name":"闭锁延迟","dataType":"varchar"},
A7: remark | B7: varchar | C7: 255 | D7: N | E7: NULL | G7: 备注 | I7: =A7&" "&B7&"("&C7&") "&E7&" "&F7&"," -> remark varchar(255) NULL , | J7: ="{""field"":"""&A7&""",""name"":"""&G7&""",""dataType"":"""&B7&"""}," -> {"field":"remark","name":"备注","dataType":"varchar"},
A8: create_time | B8: datetime | C8: 0 | D8: N | E8: NOT NULL | G8: 记录创建时间 | H8: 记录创建时间 | I8: =A8&" "&B8&"("&C8&") "&E8&" "&F8&"," -> create_time datetime(0) NOT NULL , | J8: ="{""field"":"""&A8&""",""name"":"""&G8&""",""dataType"":"""&B8&"""}," -> {"field":"create_time","name":"记录创建时间","dataType":"datetime"}, | K8: ="{""field"":"""&A8&""",""labelRegexp"":"""&G8&""",""excelRangeType"":""table""}," -> {"field":"create_time","labelRegexp":"记录创建时间","excelRangeType":"table"}, | L8: ="{""field"":"""&A8&""",""width"":150}," -> {"field":"create_time","width":150},
A9: create_user | B9: varchar | C9: 25 | D9: N | E9: NOT NULL | G9: 记录创建人 | H9: 记录创建人 | I9: =A9&" "&B9&"("&C9&") "&E9&" "&F9&"," -> create_user varchar(25) NOT NULL , | J9: ="{""field"":"""&A9&""",""name"":"""&G9&""",""dataType"":"""&B9&"""}," -> {"field":"create_user","name":"记录创建人","dataType":"varchar"}, | K9: ="{""field"":"""&A9&""",""labelRegexp"":"""&G9&""",""excelRangeType"":""table""}," -> {"field":"create_user","labelRegexp":"记录创建人","excelRangeType":"table"}, | L9: ="{""field"":"""&A9&""",""width"":150}," -> {"field":"create_user","width":150},
A10: update_time | B10: datetime | C10: 0 | D10: N | E10: NOT NULL | G10: 记录更新时间 | H10: 记录更新时间 | I10: =A10&" "&B10&"("&C10&") "&E10&" "&F10&"," -> update_time datetime(0) NOT NULL , | J10: ="{""field"":"""&A10&""",""name"":"""&G10&""",""dataType"":"""&B10&"""}," -> {"field":"update_time","name":"记录更新时间","dataType":"datetime"}, | K10: ="{""field"":"""&A10&""",""labelRegexp"":"""&G10&""",""excelRangeType"":""table""}," -> {"field":"update_time","labelRegexp":"记录更新时间","excelRangeType":"table"}, | L10: ="{""field"":"""&A10&""",""width"":150}," -> {"field":"update_time","width":150},
A11: update_user | B11: varchar | C11: 25 | D11: N | E11: NOT NULL | G11: 记录更新人 | H11: 记录更新人 | I11: =A11&" "&B11&"("&C11&") "&E11&" "&F11&"," -> update_user varchar(25) NOT NULL , | J11: ="{""field"":"""&A11&""",""name"":"""&G11&""",""dataType"":"""&B11&"""}," -> {"field":"update_user","name":"记录更新人","dataType":"varchar"}, | K11: ="{""field"":"""&A11&""",""labelRegexp"":"""&G11&""",""excelRangeType"":""table""}," -> {"field":"update_user","labelRegexp":"记录更新人","excelRangeType":"table"}, | L11: ="{""field"":"""&A11&""",""width"":150}," -> {"field":"update_user","width":150},
A12: version | B12: int | C12: 11 | D12: N | E12: NOT NULL | F12: DEFAULT 0 | G12: 数据版本号 | H12: 数据版本号 | I12: =A12&" "&B12&"("&C12&") "&E12&" "&F12&"," -> version int(11) NOT NULL DEFAULT 0, | J12: ="{""field"":"""&A12&""",""name"":"""&G12&""",""dataType"":"""&B12&"""}," -> {"field":"version","name":"数据版本号","dataType":"int"}, | K12: ="{""field"":"""&A12&""",""labelRegexp"":"""&G12&""",""excelRangeType"":""table""}," -> {"field":"version","labelRegexp":"数据版本号","excelRangeType":"table"}, | L12: ="{""field"":"""&A12&""",""width"":150}," -> {"field":"version","width":150},
I13: ="PRIMARY KEY (`id`) USING BTREE)" -> PRIMARY KEY (`id`) USING BTREE)

Sheet sl_lock_authorization_sl_person
A1: 表名： | B1: sl_lock_authorization_sl_person | C1: 说明： | D1: 智远程开锁对应施工人员关联表 | F1: 版本 | H1: 1 | I1: ="create table "&B1&" (" -> create table sl_lock_authorization_sl_person ( | N1: 目录
A2: 字段 | B2: 类型 | C2: 长度 | D2: 主键 | E2: 是否为空 | F2: 默认值 | G2: 字段名称 | H2: 说明
A3: id | B3: bigint | C3: 18 | D3: Y | E3: NOT NULL | G3: 编号 | H3: 自增ID | I3: =A3&" "&B3&"("&C3&") "&E3&" "&F3&"," -> id bigint(18) NOT NULL , | J3: ="{""field"":"""&A3&""",""name"":"""&G3&""",""dataType"":"""&B3&"""}," -> {"field":"id","name":"编号","dataType":"bigint"}, | K3: ="{""field"":"""&A3&""",""labelRegexp"":"""&G3&""",""excelRangeType"":""table""}," -> {"field":"id","labelRegexp":"编号","excelRangeType":"table"}, | L3: ="{""field"":"""&A3&""",""width"":150}," -> {"field":"id","width":150},
A4: sl_lock_authorization_id | B4: bigint | C4: 18 | D4: Y | E4: NOT NULL | G4: 编号 | H4: 授权记录ID | I4: =A4&" "&B4&"("&C4&") "&E4&" "&F4&"," -> sl_lock_authorization_id bigint(18) NOT NULL , | J4: ="{""field"":"""&A4&""",""name"":"""&G4&""",""dataType"":"""&B4&"""}," -> {"field":"sl_lock_authorization_id","name":"编号","dataType":"bigint"}, | K4: ="{""field"":"""&A4&""",""labelRegexp"":"""&G4&""",""excelRangeType"":""table""}," -> {"field":"sl_lock_authorization_id","labelRegexp":"编号","excelRangeType":"table"}, | L4: ="{""field"":"""&A4&""",""width"":150}," -> {"field":"sl_lock_authorization_id","width":150},
A5: sl_person_id | B5: varchar | C5: 20 | D5: Y | E5: NOT NULL | G5: 账号 | H5: 人员ID | I5: =A5&" "&B5&"("&C5&") "&E5&" "&F5&"," -> sl_person_id varchar(20) NOT NULL ,
A6: create_time | B6: datetime | C6: 0 | D6: N | E6: NOT NULL | G6: 记录创建时间 | H6: 记录创建时间 | I6: =A6&" "&B6&"("&C6&") "&E6&" "&F6&"," -> create_time datetime(0) NOT NULL , | J6: ="{""field"":"""&A6&""",""name"":"""&G6&""",""dataType"":"""&B6&"""}," -> {"field":"create_time","name":"记录创建时间","dataType":"datetime"}, | K6: ="{""field"":"""&A6&""",""labelRegexp"":"""&G6&""",""excelRangeType"":""table""}," -> {"field":"create_time","labelRegexp":"记录创建时间","excelRangeType":"table"}, | L6: ="{""field"":"""&A6&""",""width"":150}," -> {"field":"create_time","width":150},
A7: create_user | B7: varchar | C7: 25 | D7: N | E7: NOT NULL | G7: 记录创建人 | H7: 记录创建人 | I7: =A7&" "&B7&"("&C7&") "&E7&" "&F7&"," -> create_user varchar(25) NOT NULL , | J7: ="{""field"":"""&A7&""",""name"":"""&G7&""",""dataType"":"""&B7&"""}," -> {"field":"create_user","name":"记录创建人","dataType":"varchar"}, | K7: ="{""field"":"""&A7&""",""labelRegexp"":"""&G7&""",""excelRangeType"":""table""}," -> {"field":"create_user","labelRegexp":"记录创建人","excelRangeType":"table"}, | L7: ="{""field"":"""&A7&""",""width"":150}," -> {"field":"create_user","width":150},
A8: update_time | B8: datetime | C8: 0 | D8: N | E8: NOT NULL | G8: 记录更新时间 | H8: 记录更新时间 | I8: =A8&" "&B8&"("&C8&") "&E8&" "&F8&"," -> update_time datetime(0) NOT NULL , | J8: ="{""field"":"""&A8&""",""name"":"""&G8&""",""dataType"":"""&B8&"""}," -> {"field":"update_time","name":"记录更新时间","dataType":"datetime"}, | K8: ="{""field"":"""&A8&""",""labelRegexp"":"""&G8&""",""excelRangeType"":""table""}," -> {"field":"update_time","labelRegexp":"记录更新时间","excelRangeType":"table"}, | L8: ="{""field"":"""&A8&""",""width"":150}," -> {"field":"update_time","width":150},
A9: update_user | B9: varchar | C9: 25 | D9: N | E9: NOT NULL | G9: 记录更新人 | H9: 记录更新人 | I9: =A9&" "&B9&"("&C9&") "&E9&" "&F9&"," -> update_user varchar(25) NOT NULL , | J9: ="{""field"":"""&A9&""",""name"":"""&G9&""",""dataType"":"""&B9&"""}," -> {"field":"update_user","name":"记录更新人","dataType":"varchar"}, | K9: ="{""field"":"""&A9&""",""labelRegexp"":"""&G9&""",""excelRangeType"":""table""}," -> {"field":"update_user","labelRegexp":"记录更新人","excelRangeType":"table"}, | L9: ="{""field"":"""&A9&""",""width"":150}," -> {"field":"update_user","width":150},
A10: version | B10: int | C10: 11 | D10: N | E10: NOT NULL | F10: DEFAULT 0 | G10: 数据版本号 | H10: 数据版本号 | I10: =A10&" "&B10&"("&C10&") "&E10&" "&F10&"," -> version int(11) NOT NULL DEFAULT 0, | J10: ="{""field"":"""&A10&""",""name"":"""&G10&""",""dataType"":"""&B10&"""}," -> {"field":"version","name":"数据版本号","dataType":"int"}, | K10: ="{""field"":"""&A10&""",""labelRegexp"":"""&G10&""",""excelRangeType"":""table""}," -> {"field":"version","labelRegexp":"数据版本号","excelRangeType":"table"}, | L10: ="{""field"":"""&A10&""",""width"":150}," -> {"field":"version","width":150},
I11: ="PRIMARY KEY (`id`) USING BTREE)" -> PRIMARY KEY (`id`) USING BTREE)

Sheet sl_lock_sl_lock_authorization
A1: 表名： | B1: sl_lock_sl_lock_authorization | C1: 说明： | D1: 智远程开锁对应智能锁关联表 | F1: 版本 | H1: 1 | I1: ="create table "&B1&" (" -> create table sl_lock_sl_lock_authorization ( | N1: 目录
A2: 字段 | B2: 类型 | C2: 长度 | D2: 主键 | E2: 是否为空 | F2: 默认值 | G2: 字段名称 | H2: 说明
A3: id | B3: bigint | C3: 18 | D3: Y | E3: NOT NULL | G3: 编号 | H3: 自增ID | I3: =A3&" "&B3&"("&C3&") "&E3&" "&F3&"," -> id bigint(18) NOT NULL , | J3: ="{""field"":"""&A3&""",""name"":"""&G3&""",""dataType"":"""&B3&"""}," -> {"field":"id","name":"编号","dataType":"bigint"}, | K3: ="{""field"":"""&A3&""",""labelRegexp"":"""&G3&""",""excelRangeType"":""table""}," -> {"field":"id","labelRegexp":"编号","excelRangeType":"table"}, | L3: ="{""field"":"""&A3&""",""width"":150}," -> {"field":"id","width":150},
A4: sl_lock_id | B4: varchar | C4: 20 | D4: Y | E4: NOT NULL | G4: 编号 | H4: 智能锁ID | I4: =A4&" "&B4&"("&C4&") "&E4&" "&F4&"," -> sl_lock_id varchar(20) NOT NULL , | J4: ="{""field"":"""&A4&""",""name"":"""&G4&""",""dataType"":"""&B4&"""}," -> {"field":"sl_lock_id","name":"编号","dataType":"varchar"}, | K4: ="{""field"":"""&A4&""",""labelRegexp"":"""&G4&""",""excelRangeType"":""table""}," -> {"field":"sl_lock_id","labelRegexp":"编号","excelRangeType":"table"}, | L4: ="{""field"":"""&A4&""",""width"":150}," -> {"field":"sl_lock_id","width":150},
A5: sl_lock_authorization_id | B5: bigint | C5: 18 | D5: Y | E5: NOT NULL | G5: 编号 | H5: 授权记录ID | I5: =A5&" "&B5&"("&C5&") "&E5&" "&F5&"," -> sl_lock_authorization_id bigint(18) NOT NULL ,
A6: create_time | B6: datetime | C6: 0 | D6: N | E6: NOT NULL | G6: 记录创建时间 | H6: 记录创建时间 | I6: =A6&" "&B6&"("&C6&") "&E6&" "&F6&"," -> create_time datetime(0) NOT NULL , | J6: ="{""field"":"""&A6&""",""name"":"""&G6&""",""dataType"":"""&B6&"""}," -> {"field":"create_time","name":"记录创建时间","dataType":"datetime"}, | K6: ="{""field"":"""&A6&""",""labelRegexp"":"""&G6&""",""excelRangeType"":""table""}," -> {"field":"create_time","labelRegexp":"记录创建时间","excelRangeType":"table"}, | L6: ="{""field"":"""&A6&""",""width"":150}," -> {"field":"create_time","width":150},
A7: create_user | B7: varchar | C7: 25 | D7: N | E7: NOT NULL | G7: 记录创建人 | H7: 记录创建人 | I7: =A7&" "&B7&"("&C7&") "&E7&" "&F7&"," -> create_user varchar(25) NOT NULL , | J7: ="{""field"":"""&A7&""",""name"":"""&G7&""",""dataType"":"""&B7&"""}," -> {"field":"create_user","name":"记录创建人","dataType":"varchar"}, | K7: ="{""field"":"""&A7&""",""labelRegexp"":"""&G7&""",""excelRangeType"":""table""}," -> {"field":"create_user","labelRegexp":"记录创建人","excelRangeType":"table"}, | L7: ="{""field"":"""&A7&""",""width"":150}," -> {"field":"create_user","width":150},
A8: update_time | B8: datetime | C8: 0 | D8: N | E8: NOT NULL | G8: 记录更新时间 | H8: 记录更新时间 | I8: =A8&" "&B8&"("&C8&") "&E8&" "&F8&"," -> update_time datetime(0) NOT NULL , | J8: ="{""field"":"""&A8&""",""name"":"""&G8&""",""dataType"":"""&B8&"""}," -> {"field":"update_time","name":"记录更新时间","dataType":"datetime"}, | K8: ="{""field"":"""&A8&""",""labelRegexp"":"""&G8&""",""excelRangeType"":""table""}," -> {"field":"update_time","labelRegexp":"记录更新时间","excelRangeType":"table"}, | L8: ="{""field"":"""&A8&""",""width"":150}," -> {"field":"update_time","width":150},
A9: update_user | B9: varchar | C9: 25 | D9: N | E9: NOT NULL | G9: 记录更新人 | H9: 记录更新人 | I9: =A9&" "&B9&"("&C9&") "&E9&" "&F9&"," -> update_user varchar(25) NOT NULL , | J9: ="{""field"":"""&A9&""",""name"":"""&G9&""",""dataType"":"""&B9&"""}," -> {"field":"update_user","name":"记录更新人","dataType":"varchar"}, | K9: ="{""field"":"""&A9&""",""labelRegexp"":"""&G9&""",""excelRangeType"":""table""}," -> {"field":"update_user","labelRegexp":"记录更新人","excelRangeType":"table"}, | L9: ="{""field"":"""&A9&""",""width"":150}," -> {"field":"update_user","width":150},
A10: version | B10: int | C10: 11 | D10: N | E10: NOT NULL | F10: DEFAULT 0 | G10: 数据版本号 | H10: 数据版本号 | I10: =A10&" "&B10&"("&C10&") "&E10&" "&F10&"," -> version int(11) NOT NULL DEFAULT 0, | J10: ="{""field"":"""&A10&""",""name"":"""&G10&""",""dataType"":"""&B10&"""}," -> {"field":"version","name":"数据版本号","dataType":"int"}, | K10: ="{""field"":"""&A10&""",""labelRegexp"":"""&G10&""",""excelRangeType"":""table""}," -> {"field":"version","labelRegexp":"数据版本号","excelRangeType":"table"}, | L10: ="{""field"":"""&A10&""",""width"":150}," -> {"field":"version","width":150},
I11: ="PRIMARY KEY (`id`) USING BTREE)" -> PRIMARY KEY (`id`) USING BTREE)

Sheet sl_application_sl_key_authoriza
A1: 表名： | B1: sl_application_sl_key_authorization | C1: 说明： | D1: 钥匙授权中对应开锁申请关联表 | F1: 版本 | H1: 1 | I1: ="create table "&B1&" (" -> create table sl_application_sl_key_authorization ( | N1: 目录
A2: 字段 | B2: 类型 | C2: 长度 | D2: 主键 | E2: 是否为空 | F2: 默认值 | G2: 字段名称 | H2: 说明
A3: id | B3: bigint | C3: 18 | D3: Y | E3: NOT NULL | G3: 编号 | H3: 自增ID | I3: =A3&" "&B3&"("&C3&") "&E3&" "&F3&"," -> id bigint(18) NOT NULL , | J3: ="{""field"":"""&A3&""",""name"":"""&G3&""",""dataType"":"""&B3&"""}," -> {"field":"id","name":"编号","dataType":"bigint"}, | K3: ="{""field"":"""&A3&""",""labelRegexp"":"""&G3&""",""excelRangeType"":""table""}," -> {"field":"id","labelRegexp":"编号","excelRangeType":"table"}, | L3: ="{""field"":"""&A3&""",""width"":150}," -> {"field":"id","width":150},
A4: ls_application_id | B4: bigint | C4: 18 | D4: Y | E4: NOT NULL | G4: 编号 | H4: 开锁申请记录ID | J4: ="{""field"":"""&A4&""",""name"":"""&G4&""",""dataType"":"""&B4&"""}," -> {"field":"ls_application_id","name":"编号","dataType":"bigint"}, | K4: ="{""field"":"""&A4&""",""labelRegexp"":"""&G4&""",""excelRangeType"":""table""}," -> {"field":"ls_application_id","labelRegexp":"编号","excelRangeType":"table"}, | L4: ="{""field"":"""&A4&""",""width"":150}," -> {"field":"ls_application_id","width":150},
A5: sl_key_authorization_id | B5: bigint | C5: 18 | D5: Y | E5: NOT NULL | G5: 编号 | H5: 钥匙授权记录ID
A6: create_time | B6: datetime | C6: 0 | D6: N | E6: NOT NULL | G6: 记录创建时间 | H6: 记录创建时间 | I6: =A6&" "&B6&"("&C6&") "&E6&" "&F6&"," -> create_time datetime(0) NOT NULL , | J6: ="{""field"":"""&A6&""",""name"":"""&G6&""",""dataType"":"""&B6&"""}," -> {"field":"create_time","name":"记录创建时间","dataType":"datetime"}, | K6: ="{""field"":"""&A6&""",""labelRegexp"":"""&G6&""",""excelRangeType"":""table""}," -> {"field":"create_time","labelRegexp":"记录创建时间","excelRangeType":"table"}, | L6: ="{""field"":"""&A6&""",""width"":150}," -> {"field":"create_time","width":150},
A7: create_user | B7: varchar | C7: 25 | D7: N | E7: NOT NULL | G7: 记录创建人 | H7: 记录创建人 | I7: =A7&" "&B7&"("&C7&") "&E7&" "&F7&"," -> create_user varchar(25) NOT NULL , | J7: ="{""field"":"""&A7&""",""name"":"""&G7&""",""dataType"":"""&B7&"""}," -> {"field":"create_user","name":"记录创建人","dataType":"varchar"}, | K7: ="{""field"":"""&A7&""",""labelRegexp"":"""&G7&""",""excelRangeType"":""table""}," -> {"field":"create_user","labelRegexp":"记录创建人","excelRangeType":"table"}, | L7: ="{""field"":"""&A7&""",""width"":150}," -> {"field":"create_user","width":150},
A8: update_time | B8: datetime | C8: 0 | D8: N | E8: NOT NULL | G8: 记录更新时间 | H8: 记录更新时间 | I8: =A8&" "&B8&"("&C8&") "&E8&" "&F8&"," -> update_time datetime(0) NOT NULL , | J8: ="{""field"":"""&A8&""",""name"":"""&G8&""",""dataType"":"""&B8&"""}," -> {"field":"update_time","name":"记录更新时间","dataType":"datetime"}, | K8: ="{""field"":"""&A8&""",""labelRegexp"":"""&G8&""",""excelRangeType"":""table""}," -> {"field":"update_time","labelRegexp":"记录更新时间","excelRangeType":"table"}, | L8: ="{""field"":"""&A8&""",""width"":150}," -> {"field":"update_time","width":150},
A9: update_user | B9: varchar | C9: 25 | D9: N | E9: NOT NULL | G9: 记录更新人 | H9: 记录更新人 | I9: =A9&" "&B9&"("&C9&") "&E9&" "&F9&"," -> update_user varchar(25) NOT NULL , | J9: ="{""field"":"""&A9&""",""name"":"""&G9&""",""dataType"":"""&B9&"""}," -> {"field":"update_user","name":"记录更新人","dataType":"varchar"}, | K9: ="{""field"":"""&A9&""",""labelRegexp"":"""&G9&""",""excelRangeType"":""table""}," -> {"field":"update_user","labelRegexp":"记录更新人","excelRangeType":"table"}, | L9: ="{""field"":"""&A9&""",""width"":150}," -> {"field":"update_user","width":150},
A10: version | B10: int | C10: 11 | D10: N | E10: NOT NULL | F10: DEFAULT 0 | G10: 数据版本号 | H10: 数据版本号 | I10: =A10&" "&B10&"("&C10&") "&E10&" "&F10&"," -> version int(11) NOT NULL DEFAULT 0, | J10: ="{""field"":"""&A10&""",""name"":"""&G10&""",""dataType"":"""&B10&"""}," -> {"field":"version","name":"数据版本号","dataType":"int"}, | K10: ="{""field"":"""&A10&""",""labelRegexp"":"""&G10&""",""excelRangeType"":""table""}," -> {"field":"version","labelRegexp":"数据版本号","excelRangeType":"table"}, | L10: ="{""field"":"""&A10&""",""width"":150}," -> {"field":"version","width":150},
I11: ="PRIMARY KEY (`id`) USING BTREE)" -> PRIMARY KEY (`id`) USING BTREE)

Sheet sl_key_authorization
A1: 表名： | B1: sl_key_authorization | C1: 说明： | D1: 智能钥匙授权记录表 | F1: 版本 | H1: 1 | I1: ="create table "&B1&" (" -> create table sl_key_authorization ( | N1: 目录
A2: 字段 | B2: 类型 | C2: 长度 | D2: 主键 | E2: 是否为空 | F2: 默认值 | G2: 字段名称 | H2: 说明
A3: id | B3: bigint | C3: 18 | D3: Y | E3: NOT NULL | G3: 编号 | H3: 自增ID | I3: =A3&" "&B3&"("&C3&") "&E3&" "&F3&"," -> id bigint(18) NOT NULL , | J3: ="{""field"":"""&A3&""",""name"":"""&G3&""",""dataType"":"""&B3&"""}," -> {"field":"id","name":"编号","dataType":"bigint"}, | K3: ="{""field"":"""&A3&""",""labelRegexp"":"""&G3&""",""excelRangeType"":""table""}," -> {"field":"id","labelRegexp":"编号","excelRangeType":"table"}, | L3: ="{""field"":"""&A3&""",""width"":150}," -> {"field":"id","width":150},
A4: key_controller_id | B4: varchar | C4: 20 | D4: N | E4: NOT NULL | G4: 智能钥匙管理机 | H4: 智能钥匙管理机表外键 | I4: =A4&" "&B4&"("&C4&") "&E4&" "&F4&"," -> key_controller_id varchar(20) NOT NULL , | J4: ="{""field"":"""&A4&""",""name"":"""&G4&""",""dataType"":"""&B4&"""}," -> {"field":"key_controller_id","name":"智能钥匙管理机","dataType":"varchar"}, | K4: ="{""field"":"""&A4&""",""labelRegexp"":"""&G4&""",""excelRangeType"":""table""}," -> {"field":"key_controller_id","labelRegexp":"智能钥匙管理机","excelRangeType":"table"}, | L4: ="{""field"":"""&A4&""",""width"":150}," -> {"field":"key_controller_id","width":150},
A5: key_id | B5: varchar | C5: 20 | D5: N | E5: NOT NULL | G5: 智能钥匙 | H5: 智能钥匙表外键 | I5: =A5&" "&B5&"("&C5&") "&E5&" "&F5&"," -> key_id varchar(20) NOT NULL , | J5: ="{""field"":"""&A5&""",""name"":"""&G5&""",""dataType"":"""&B5&"""}," -> {"field":"key_id","name":"智能钥匙","dataType":"varchar"}, | L5: ="{""field"":"""&A5&""",""width"":150}," -> {"field":"key_id","width":150},
A6: remark | B6: varchar | C6: 255 | D6: N | E6: NULL | G6: 备注 | I6: =A6&" "&B6&"("&C6&") "&E6&" "&F6&"," -> remark varchar(255) NULL , | J6: ="{""field"":"""&A6&""",""name"":"""&G6&""",""dataType"":"""&B6&"""}," -> {"field":"remark","name":"备注","dataType":"varchar"}, | L6: ="{""field"":"""&A6&""",""width"":150}," -> {"field":"remark","width":150},
A7: applications | H7: 多对多对应到授权申请表 | J7: ="{""field"":"""&A7&""",""name"":"""&G7&""",""dataType"":"""&B7&"""}," -> {"field":"applications","name":"","dataType":""}, | L7: ="{""field"":"""&A7&""",""width"":150}," -> {"field":"applications","width":150},
A8: create_time | B8: datetime | C8: 0 | D8: N | E8: NOT NULL | G8: 记录创建时间 | H8: 记录创建时间 | I8: =A8&" "&B8&"("&C8&") "&E8&" "&F8&"," -> create_time datetime(0) NOT NULL , | J8: ="{""field"":"""&A8&""",""name"":"""&G8&""",""dataType"":"""&B8&"""}," -> {"field":"create_time","name":"记录创建时间","dataType":"datetime"}, | K8: ="{""field"":"""&A8&""",""labelRegexp"":"""&G8&""",""excelRangeType"":""table""}," -> {"field":"create_time","labelRegexp":"记录创建时间","excelRangeType":"table"}, | L8: ="{""field"":"""&A8&""",""width"":150}," -> {"field":"create_time","width":150},
A9: create_user | B9: varchar | C9: 25 | D9: N | E9: NOT NULL | G9: 记录创建人 | H9: 记录创建人 | I9: =A9&" "&B9&"("&C9&") "&E9&" "&F9&"," -> create_user varchar(25) NOT NULL , | J9: ="{""field"":"""&A9&""",""name"":"""&G9&""",""dataType"":"""&B9&"""}," -> {"field":"create_user","name":"记录创建人","dataType":"varchar"}, | K9: ="{""field"":"""&A9&""",""labelRegexp"":"""&G9&""",""excelRangeType"":""table""}," -> {"field":"create_user","labelRegexp":"记录创建人","excelRangeType":"table"}, | L9: ="{""field"":"""&A9&""",""width"":150}," -> {"field":"create_user","width":150},
A10: update_time | B10: datetime | C10: 0 | D10: N | E10: NOT NULL | G10: 记录更新时间 | H10: 记录更新时间 | I10: =A10&" "&B10&"("&C10&") "&E10&" "&F10&"," -> update_time datetime(0) NOT NULL , | J10: ="{""field"":"""&A10&""",""name"":"""&G10&""",""dataType"":"""&B10&"""}," -> {"field":"update_time","name":"记录更新时间","dataType":"datetime"}, | K10: ="{""field"":"""&A10&""",""labelRegexp"":"""&G10&""",""excelRangeType"":""table""}," -> {"field":"update_time","labelRegexp":"记录更新时间","excelRangeType":"table"}, | L10: ="{""field"":"""&A10&""",""width"":150}," -> {"field":"update_time","width":150},
A11: update_user | B11: varchar | C11: 25 | D11: N | E11: NOT NULL | G11: 记录更新人 | H11: 记录更新人 | I11: =A11&" "&B11&"("&C11&") "&E11&" "&F11&"," -> update_user varchar(25) NOT NULL , | J11: ="{""field"":"""&A11&""",""name"":"""&G11&""",""dataType"":"""&B11&"""}," -> {"field":"update_user","name":"记录更新人","dataType":"varchar"}, | K11: ="{""field"":"""&A11&""",""labelRegexp"":"""&G11&""",""excelRangeType"":""table""}," -> {"field":"update_user","labelRegexp":"记录更新人","excelRangeType":"table"}, | L11: ="{""field"":"""&A11&""",""width"":150}," -> {"field":"update_user","width":150},
A12: version | B12: int | C12: 11 | D12: N | E12: NOT NULL | F12: DEFAULT 0 | G12: 数据版本号 | H12: 数据版本号 | I12: =A12&" "&B12&"("&C12&") "&E12&" "&F12&"," -> version int(11) NOT NULL DEFAULT 0, | J12: ="{""field"":"""&A12&""",""name"":"""&G12&""",""dataType"":"""&B12&"""}," -> {"field":"version","name":"数据版本号","dataType":"int"}, | K12: ="{""field"":"""&A12&""",""labelRegexp"":"""&G12&""",""excelRangeType"":""table""}," -> {"field":"version","labelRegexp":"数据版本号","excelRangeType":"table"}, | L12: ="{""field"":"""&A12&""",""width"":150}," -> {"field":"version","width":150},
I13: ="PRIMARY KEY (`id`) USING BTREE)" -> PRIMARY KEY (`id`) USING BTREE)

Sheet sl_application_sl_person
A1: 表名： | B1: sl_application_sl_person | C1: 说明： | D1: 开锁申请对应施工人员关联表 | F1: 版本 | H1: 1 | I1: ="create table "&B1&" (" -> create table sl_application_sl_person ( | N1: 目录
A2: 字段 | B2: 类型 | C2: 长度 | D2: 主键 | E2: 是否为空 | F2: 默认值 | G2: 字段名称 | H2: 说明
A3: id | B3: bigint | C3: 18 | D3: Y | E3: NOT NULL | G3: 编号 | H3: 自增ID | I3: =A3&" "&B3&"("&C3&") "&E3&" "&F3&"," -> id bigint(18) NOT NULL , | J3: ="{""field"":"""&A3&""",""name"":"""&G3&""",""dataType"":"""&B3&"""}," -> {"field":"id","name":"编号","dataType":"bigint"}, | K3: ="{""field"":"""&A3&""",""labelRegexp"":"""&G3&""",""excelRangeType"":""table""}," -> {"field":"id","labelRegexp":"编号","excelRangeType":"table"}, | L3: ="{""field"":"""&A3&""",""width"":150}," -> {"field":"id","width":150},
A4: sl_application_id | B4: bigint | C4: 18 | D4: Y | E4: NOT NULL | G4: 编号 | H4: 开锁申请记录ID | I4: =A4&" "&B4&"("&C4&") "&E4&" "&F4&"," -> sl_application_id bigint(18) NOT NULL , | J4: ="{""field"":"""&A4&""",""name"":"""&G4&""",""dataType"":"""&B4&"""}," -> {"field":"sl_application_id","name":"编号","dataType":"bigint"}, | K4: ="{""field"":"""&A4&""",""labelRegexp"":"""&G4&""",""excelRangeType"":""table""}," -> {"field":"sl_application_id","labelRegexp":"编号","excelRangeType":"table"}, | L4: ="{""field"":"""&A4&""",""width"":150}," -> {"field":"sl_application_id","width":150},
A5: sl_person_id | B5: varchar | C5: 20 | D5: Y | E5: NOT NULL | G5: 账号 | H5: 人员ID | I5: =A5&" "&B5&"("&C5&") "&E5&" "&F5&"," -> sl_person_id varchar(20) NOT NULL ,
A6: create_time | B6: datetime | C6: 0 | D6: N | E6: NOT NULL | G6: 记录创建时间 | H6: 记录创建时间 | I6: =A6&" "&B6&"("&C6&") "&E6&" "&F6&"," -> create_time datetime(0) NOT NULL , | J6: ="{""field"":"""&A6&""",""name"":"""&G6&""",""dataType"":"""&B6&"""}," -> {"field":"create_time","name":"记录创建时间","dataType":"datetime"}, | K6: ="{""field"":"""&A6&""",""labelRegexp"":"""&G6&""",""excelRangeType"":""table""}," -> {"field":"create_time","labelRegexp":"记录创建时间","excelRangeType":"table"}, | L6: ="{""field"":"""&A6&""",""width"":150}," -> {"field":"create_time","width":150},
A7: create_user | B7: varchar | C7: 25 | D7: N | E7: NOT NULL | G7: 记录创建人 | H7: 记录创建人 | I7: =A7&" "&B7&"("&C7&") "&E7&" "&F7&"," -> create_user varchar(25) NOT NULL , | J7: ="{""field"":"""&A7&""",""name"":"""&G7&""",""dataType"":"""&B7&"""}," -> {"field":"create_user","name":"记录创建人","dataType":"varchar"}, | K7: ="{""field"":"""&A7&""",""labelRegexp"":"""&G7&""",""excelRangeType"":""table""}," -> {"field":"create_user","labelRegexp":"记录创建人","excelRangeType":"table"}, | L7: ="{""field"":"""&A7&""",""width"":150}," -> {"field":"create_user","width":150},
A8: update_time | B8: datetime | C8: 0 | D8: N | E8: NOT NULL | G8: 记录更新时间 | H8: 记录更新时间 | I8: =A8&" "&B8&"("&C8&") "&E8&" "&F8&"," -> update_time datetime(0) NOT NULL , | J8: ="{""field"":"""&A8&""",""name"":"""&G8&""",""dataType"":"""&B8&"""}," -> {"field":"update_time","name":"记录更新时间","dataType":"datetime"}, | K8: ="{""field"":"""&A8&""",""labelRegexp"":"""&G8&""",""excelRangeType"":""table""}," -> {"field":"update_time","labelRegexp":"记录更新时间","excelRangeType":"table"}, | L8: ="{""field"":"""&A8&""",""width"":150}," -> {"field":"update_time","width":150},
A9: update_user | B9: varchar | C9: 25 | D9: N | E9: NOT NULL | G9: 记录更新人 | H9: 记录更新人 | I9: =A9&" "&B9&"("&C9&") "&E9&" "&F9&"," -> update_user varchar(25) NOT NULL , | J9: ="{""field"":"""&A9&""",""name"":"""&G9&""",""dataType"":"""&B9&"""}," -> {"field":"update_user","name":"记录更新人","dataType":"varchar"}, | K9: ="{""field"":"""&A9&""",""labelRegexp"":"""&G9&""",""excelRangeType"":""table""}," -> {"field":"update_user","labelRegexp":"记录更新人","excelRangeType":"table"}, | L9: ="{""field"":"""&A9&""",""width"":150}," -> {"field":"update_user","width":150},
A10: version | B10: int | C10: 11 | D10: N | E10: NOT NULL | F10: DEFAULT 0 | G10: 数据版本号 | H10: 数据版本号 | I10: =A10&" "&B10&"("&C10&") "&E10&" "&F10&"," -> version int(11) NOT NULL DEFAULT 0, | J10: ="{""field"":"""&A10&""",""name"":"""&G10&""",""dataType"":"""&B10&"""}," -> {"field":"version","name":"数据版本号","dataType":"int"}, | K10: ="{""field"":"""&A10&""",""labelRegexp"":"""&G10&""",""excelRangeType"":""table""}," -> {"field":"version","labelRegexp":"数据版本号","excelRangeType":"table"}, | L10: ="{""field"":"""&A10&""",""width"":150}," -> {"field":"version","width":150},
I11: ="PRIMARY KEY (`id`) USING BTREE)" -> PRIMARY KEY (`id`) USING BTREE)

Sheet sl_application_sl_lock
A1: 表名： | B1: sl_application_sl_lock | C1: 说明： | D1: 开锁申请对应智能锁关联表 | F1: 版本 | H1: 1 | I1: ="create table "&B1&" (" -> create table sl_application_sl_lock ( | N1: 目录
A2: 字段 | B2: 类型 | C2: 长度 | D2: 主键 | E2: 是否为空 | F2: 默认值 | G2: 字段名称 | H2: 说明
A3: id | B3: bigint | C3: 18 | D3: Y | E3: NOT NULL | G3: 编号 | H3: 自增ID | I3: =A3&" "&B3&"("&C3&") "&E3&" "&F3&"," -> id bigint(18) NOT NULL , | J3: ="{""field"":"""&A3&""",""name"":"""&G3&""",""dataType"":"""&B3&"""}," -> {"field":"id","name":"编号","dataType":"bigint"}, | K3: ="{""field"":"""&A3&""",""labelRegexp"":"""&G3&""",""excelRangeType"":""table""}," -> {"field":"id","labelRegexp":"编号","excelRangeType":"table"}, | L3: ="{""field"":"""&A3&""",""width"":150}," -> {"field":"id","width":150},
A4: sl_lock_id | B4: varchar | C4: 20 | D4: Y | E4: NOT NULL | G4: 编号 | H4: 智能锁ID | I4: =A4&" "&B4&"("&C4&") "&E4&" "&F4&"," -> sl_lock_id varchar(20) NOT NULL , | J4: ="{""field"":"""&A4&""",""name"":"""&G4&""",""dataType"":"""&B4&"""}," -> {"field":"sl_lock_id","name":"编号","dataType":"varchar"}, | K4: ="{""field"":"""&A4&""",""labelRegexp"":"""&G4&""",""excelRangeType"":""table""}," -> {"field":"sl_lock_id","labelRegexp":"编号","excelRangeType":"table"}, | L4: ="{""field"":"""&A4&""",""width"":150}," -> {"field":"sl_lock_id","width":150},
A5: sl_application_id | B5: bigint | C5: 18 | D5: Y | E5: NOT NULL | G5: 编号 | H5: 开锁申请记录ID | I5: =A5&" "&B5&"("&C5&") "&E5&" "&F5&"," -> sl_application_id bigint(18) NOT NULL ,
A6: create_time | B6: datetime | C6: 0 | D6: N | E6: NOT NULL | G6: 记录创建时间 | H6: 记录创建时间 | I6: =A6&" "&B6&"("&C6&") "&E6&" "&F6&"," -> create_time datetime(0) NOT NULL , | J6: ="{""field"":"""&A6&""",""name"":"""&G6&""",""dataType"":"""&B6&"""}," -> {"field":"create_time","name":"记录创建时间","dataType":"datetime"}, | K6: ="{""field"":"""&A6&""",""labelRegexp"":"""&G6&""",""excelRangeType"":""table""}," -> {"field":"create_time","labelRegexp":"记录创建时间","excelRangeType":"table"}, | L6: ="{""field"":"""&A6&""",""width"":150}," -> {"field":"create_time","width":150},
A7: create_user | B7: varchar | C7: 25 | D7: N | E7: NOT NULL | G7: 记录创建人 | H7: 记录创建人 | I7: =A7&" "&B7&"("&C7&") "&E7&" "&F7&"," -> create_user varchar(25) NOT NULL , | J7: ="{""field"":"""&A7&""",""name"":"""&G7&""",""dataType"":"""&B7&"""}," -> {"field":"create_user","name":"记录创建人","dataType":"varchar"}, | K7: ="{""field"":"""&A7&""",""labelRegexp"":"""&G7&""",""excelRangeType"":""table""}," -> {"field":"create_user","labelRegexp":"记录创建人","excelRangeType":"table"}, | L7: ="{""field"":"""&A7&""",""width"":150}," -> {"field":"create_user","width":150},
A8: update_time | B8: datetime | C8: 0 | D8: N | E8: NOT NULL | G8: 记录更新时间 | H8: 记录更新时间 | I8: =A8&" "&B8&"("&C8&") "&E8&" "&F8&"," -> update_time datetime(0) NOT NULL , | J8: ="{""field"":"""&A8&""",""name"":"""&G8&""",""dataType"":"""&B8&"""}," -> {"field":"update_time","name":"记录更新时间","dataType":"datetime"}, | K8: ="{""field"":"""&A8&""",""labelRegexp"":"""&G8&""",""excelRangeType"":""table""}," -> {"field":"update_time","labelRegexp":"记录更新时间","excelRangeType":"table"}, | L8: ="{""field"":"""&A8&""",""width"":150}," -> {"field":"update_time","width":150},
A9: update_user | B9: varchar | C9: 25 | D9: N | E9: NOT NULL | G9: 记录更新人 | H9: 记录更新人 | I9: =A9&" "&B9&"("&C9&") "&E9&" "&F9&"," -> update_user varchar(25) NOT NULL , | J9: ="{""field"":"""&A9&""",""name"":"""&G9&""",""dataType"":"""&B9&"""}," -> {"field":"update_user","name":"记录更新人","dataType":"varchar"}, | K9: ="{""field"":"""&A9&""",""labelRegexp"":"""&G9&""",""excelRangeType"":""table""}," -> {"field":"update_user","labelRegexp":"记录更新人","excelRangeType":"table"}, | L9: ="{""field"":"""&A9&""",""width"":150}," -> {"field":"update_user","width":150},
A10: version | B10: int | C10: 11 | D10: N | E10: NOT NULL | F10: DEFAULT 0 | G10: 数据版本号 | H10: 数据版本号 | I10: =A10&" "&B10&"("&C10&") "&E10&" "&F10&"," -> version int(11) NOT NULL DEFAULT 0, | J10: ="{""field"":"""&A10&""",""name"":"""&G10&""",""dataType"":"""&B10&"""}," -> {"field":"version","name":"数据版本号","dataType":"int"}, | K10: ="{""field"":"""&A10&""",""labelRegexp"":"""&G10&""",""excelRangeType"":""table""}," -> {"field":"version","labelRegexp":"数据版本号","excelRangeType":"table"}, | L10: ="{""field"":"""&A10&""",""width"":150}," -> {"field":"version","width":150},
I11: ="PRIMARY KEY (`id`) USING BTREE)" -> PRIMARY KEY (`id`) USING BTREE)

Sheet sl_application
A1: 表名： | B1: sl_application | C1: 说明： | D1: 智能锁开锁申请 | F1: 版本 | H1: 1 | I1: ="create table "&B1&" (" -> create table sl_application ( | N1: 目录
A2: 字段 | B2: 类型 | C2: 长度 | D2: 主键 | E2: 是否为空 | F2: 默认值 | G2: 字段名称 | H2: 说明
A3: id | B3: bigint | C3: 18 | D3: Y | E3: NOT NULL | G3: 编号 | H3: 自增ID | I3: =A3&" "&B3&"("&C3&") "&E3&" "&F3&"," -> id bigint(18) NOT NULL , | J3: ="{""field"":"""&A3&""",""name"":"""&G3&""",""dataType"":"""&B3&"""}," -> {"field":"id","name":"编号","dataType":"bigint"}, | K3: ="{""field"":"""&A3&""",""labelRegexp"":"""&G3&""",""excelRangeType"":""table""}," -> {"field":"id","labelRegexp":"编号","excelRangeType":"table"}, | L3: ="{""field"":"""&A3&""",""width"":150}," -> {"field":"id","width":150},
A4: locks | B4: varchar | C4: 20 | D4: N | E4: NOT NULL | G4: 智能锁ID | H4: 多对多关联智能锁表 | J4: ="{""field"":"""&A4&""",""name"":"""&G4&""",""dataType"":"""&B4&"""}," -> {"field":"locks","name":"智能锁ID","dataType":"varchar"}, | K4: ="{""field"":"""&A4&""",""labelRegexp"":"""&G4&""",""excelRangeType"":""table""}," -> {"field":"locks","labelRegexp":"智能锁ID","excelRangeType":"table"}, | L4: ="{""field"":"""&A4&""",""width"":150}," -> {"field":"locks","width":150},
A5: operators | B5: varchar | C5: 20 | D5: N | E5: NOT NULL | G5: 操作人 | H5: 多对多关联人员表 | J5: ="{""field"":"""&A5&""",""name"":"""&G5&""",""dataType"":"""&B5&"""}," -> {"field":"operators","name":"操作人","dataType":"varchar"}, | L5: ="{""field"":"""&A5&""",""width"":150}," -> {"field":"operators","width":150},
A6: key_controller | B6: varchar | C6: 20 | D6: N | E6: NOT NULL | G6: 钥匙管理机
A7: approver | B7: varchar | C7: 20 | D7: N | E7: NOT NULL | G7: 审批人 | H7: 人员表外键 | I7: =A7&" "&B7&"("&C7&") "&E7&" "&F7&"," -> approver varchar(20) NOT NULL , | J7: ="{""field"":"""&A7&""",""name"":"""&G7&""",""dataType"":"""&B7&"""}," -> {"field":"approver","name":"审批人","dataType":"varchar"}, | L7: ="{""field"":"""&A7&""",""width"":150}," -> {"field":"approver","width":150},
A8: start_date | B8: datetime | C8: 0 | D8: N | E8: NOT NULL | G8: 开始日期 | I8: =A8&" "&B8&"("&C8&") "&E8&" "&F8&"," -> start_date datetime(0) NOT NULL , | J8: ="{""field"":"""&A8&""",""name"":"""&G8&""",""dataType"":"""&B8&"""}," -> {"field":"start_date","name":"开始日期","dataType":"datetime"}, | L8: ="{""field"":"""&A8&""",""width"":150}," -> {"field":"start_date","width":150},
A9: end_date | B9: datetime | C9: 0 | D9: N | E9: NOT NULL | G9: 截止日期 | I9: =A9&" "&B9&"("&C9&") "&E9&" "&F9&"," -> end_date datetime(0) NOT NULL , | J9: ="{""field"":"""&A9&""",""name"":"""&G9&""",""dataType"":"""&B9&"""}," -> {"field":"end_date","name":"截止日期","dataType":"datetime"}, | L9: ="{""field"":"""&A9&""",""width"":150}," -> {"field":"end_date","width":150},
A10: start_time | B10: time | C10: 0 | D10: N | E10: NOT NULL | G10: 开始时间 | I10: =A10&" "&B10&"("&C10&") "&E10&" "&F10&"," -> start_time time(0) NOT NULL , | J10: ="{""field"":"""&A10&""",""name"":"""&G10&""",""dataType"":"""&B10&"""}," -> {"field":"start_time","name":"开始时间","dataType":"time"}, | L10: ="{""field"":"""&A10&""",""width"":150}," -> {"field":"start_time","width":150},
A11: end_time | B11: time | C11: 0 | D11: N | E11: NOT NULL | G11: 截止时间 | I11: =A11&" "&B11&"("&C11&") "&E11&" "&F11&"," -> end_time time(0) NOT NULL , | J11: ="{""field"":"""&A11&""",""name"":"""&G11&""",""dataType"":"""&B11&"""}," -> {"field":"end_time","name":"截止时间","dataType":"time"}, | L11: ="{""field"":"""&A11&""",""width"":150}," -> {"field":"end_time","width":150},
A12: description | B12: varchar | C12: 255 | D12: N | E12: NULL | G12: 事由说明 | I12: =A12&" "&B12&"("&C12&") "&E12&" "&F12&"," -> description varchar(255) NULL , | J12: ="{""field"":"""&A12&""",""name"":"""&G12&""",""dataType"":"""&B12&"""}," -> {"field":"description","name":"事由说明","dataType":"varchar"}, | L12: ="{""field"":"""&A12&""",""width"":150}," -> {"field":"description","width":150},
A13: status | B13: varchar | C13: 2 | D13: N | E13: NOT NULL | F13: DEFAULT '0' | G13: 状态 | H13: 0--草稿 1--审批中 2--审批通过 3--审批拒绝 | I13: =A13&" "&B13&"("&C13&") "&E13&" "&F13&"," -> status varchar(2) NOT NULL DEFAULT '0', | J13: ="{""field"":"""&A13&""",""name"":"""&G13&""",""dataType"":"""&B13&"""}," -> {"field":"status","name":"状态","dataType":"varchar"}, | L13: ="{""field"":"""&A13&""",""width"":150}," -> {"field":"status","width":150},
A14: approval_comments | B14: varchar | C14: 255 | D14: N | E14: NULL | G14: 审批意见 | I14: =A14&" "&B14&"("&C14&") "&E14&" "&F14&"," -> approval_comments varchar(255) NULL , | J14: ="{""field"":"""&A14&""",""name"":"""&G14&""",""dataType"":"""&B14&"""}," -> {"field":"approval_comments","name":"审批意见","dataType":"varchar"}, | L14: ="{""field"":"""&A14&""",""width"":150}," -> {"field":"approval_comments","width":150},
A15: create_time | B15: datetime | C15: 0 | D15: N | E15: NOT NULL | G15: 记录创建时间 | H15: 记录创建时间 | I15: =A15&" "&B15&"("&C15&") "&E15&" "&F15&"," -> create_time datetime(0) NOT NULL , | J15: ="{""field"":"""&A15&""",""name"":"""&G15&""",""dataType"":"""&B15&"""}," -> {"field":"create_time","name":"记录创建时间","dataType":"datetime"}, | K15: ="{""field"":"""&A15&""",""labelRegexp"":"""&G15&""",""excelRangeType"":""table""}," -> {"field":"create_time","labelRegexp":"记录创建时间","excelRangeType":"table"}, | L15: ="{""field"":"""&A15&""",""width"":150}," -> {"field":"create_time","width":150},
A16: create_user | B16: varchar | C16: 25 | D16: N | E16: NOT NULL | G16: 记录创建人 | H16: 记录创建人 | I16: =A16&" "&B16&"("&C16&") "&E16&" "&F16&"," -> create_user varchar(25) NOT NULL , | J16: ="{""field"":"""&A16&""",""name"":"""&G16&""",""dataType"":"""&B16&"""}," -> {"field":"create_user","name":"记录创建人","dataType":"varchar"}, | K16: ="{""field"":"""&A16&""",""labelRegexp"":"""&G16&""",""excelRangeType"":""table""}," -> {"field":"create_user","labelRegexp":"记录创建人","excelRangeType":"table"}, | L16: ="{""field"":"""&A16&""",""width"":150}," -> {"field":"create_user","width":150},
A17: update_time | B17: datetime | C17: 0 | D17: N | E17: NOT NULL | G17: 记录更新时间 | H17: 记录更新时间 | I17: =A17&" "&B17&"("&C17&") "&E17&" "&F17&"," -> update_time datetime(0) NOT NULL , | J17: ="{""field"":"""&A17&""",""name"":"""&G17&""",""dataType"":"""&B17&"""}," -> {"field":"update_time","name":"记录更新时间","dataType":"datetime"}, | K17: ="{""field"":"""&A17&""",""labelRegexp"":"""&G17&""",""excelRangeType"":""table""}," -> {"field":"update_time","labelRegexp":"记录更新时间","excelRangeType":"table"}, | L17: ="{""field"":"""&A17&""",""width"":150}," -> {"field":"update_time","width":150},
A18: update_user | B18: varchar | C18: 25 | D18: N | E18: NOT NULL | G18: 记录更新人 | H18: 记录更新人 | I18: =A18&" "&B18&"("&C18&") "&E18&" "&F18&"," -> update_user varchar(25) NOT NULL , | J18: ="{""field"":"""&A18&""",""name"":"""&G18&""",""dataType"":"""&B18&"""}," -> {"field":"update_user","name":"记录更新人","dataType":"varchar"}, | K18: ="{""field"":"""&A18&""",""labelRegexp"":"""&G18&""",""excelRangeType"":""table""}," -> {"field":"update_user","labelRegexp":"记录更新人","excelRangeType":"table"}, | L18: ="{""field"":"""&A18&""",""width"":150}," -> {"field":"update_user","width":150},
A19: version | B19: int | C19: 11 | D19: N | E19: NOT NULL | F19: DEFAULT 0 | G19: 数据版本号 | H19: 数据版本号 | I19: =A19&" "&B19&"("&C19&") "&E19&" "&F19&"," -> version int(11) NOT NULL DEFAULT 0, | J19: ="{""field"":"""&A19&""",""name"":"""&G19&""",""dataType"":"""&B19&"""}," -> {"field":"version","name":"数据版本号","dataType":"int"}, | K19: ="{""field"":"""&A19&""",""labelRegexp"":"""&G19&""",""excelRangeType"":""table""}," -> {"field":"version","labelRegexp":"数据版本号","excelRangeType":"table"}, | L19: ="{""field"":"""&A19&""",""width"":150}," -> {"field":"version","width":150},
I20: ="PRIMARY KEY (`id`) USING BTREE)" -> PRIMARY KEY (`id`) USING BTREE)

Sheet sl_lock_status_record
A1: 表名： | B1: sl_lock_status_record | C1: 说明： | D1: 智能锁状态记录表 | F1: 版本 | H1: 1 | I1: ="create table "&B1&" (" -> create table sl_lock_status_record ( | N1: 目录
A2: 字段 | B2: 类型 | C2: 长度 | D2: 主键 | E2: 是否为空 | F2: 默认值 | G2: 字段名称 | H2: 说明
A3: id | B3: bigint | C3: 18 | D3: Y | E3: NOT NULL | G3: 编号 | H3: 自增ID | I3: =A3&" "&B3&"("&C3&") "&E3&" "&F3&"," -> id bigint(18) NOT NULL , | J3: ="{""field"":"""&A3&""",""name"":"""&G3&""",""dataType"":"""&B3&"""}," -> {"field":"id","name":"编号","dataType":"bigint"}, | K3: ="{""field"":"""&A3&""",""labelRegexp"":"""&G3&""",""excelRangeType"":""table""}," -> {"field":"id","labelRegexp":"编号","excelRangeType":"table"}, | L3: ="{""field"":"""&A3&""",""width"":150}," -> {"field":"id","width":150},
A4: lock_id | B4: varchar | C4: 20 | D4: N | E4: NOT NULL | G4: 智能锁ID | H4: 智能锁信息表外键 | I4: =A4&" "&B4&"("&C4&") "&E4&" "&F4&"," -> lock_id varchar(20) NOT NULL , | J4: ="{""field"":"""&A4&""",""name"":"""&G4&""",""dataType"":"""&B4&"""}," -> {"field":"lock_id","name":"智能锁ID","dataType":"varchar"}, | K4: ="{""field"":"""&A4&""",""labelRegexp"":"""&G4&""",""excelRangeType"":""table""}," -> {"field":"lock_id","labelRegexp":"智能锁ID","excelRangeType":"table"}, | L4: ="{""field"":"""&A4&""",""width"":150}," -> {"field":"lock_id","width":150},
A5: status | B5: varchar | C5: 3 | D5: N | E5: NOT NULL | G5: 状态/事件 | H5: 000:门开锁开 001:门开锁关 010:门关锁开 011:门关锁关 | I5: =A5&" "&B5&"("&C5&") "&E5&" "&F5&"," -> status varchar(3) NOT NULL , | J5: ="{""field"":"""&A5&""",""name"":"""&G5&""",""dataType"":"""&B5&"""}," -> {"field":"status","name":"状态/事件","dataType":"varchar"}, | L5: ="{""field"":"""&A5&""",""width"":150}," -> {"field":"status","width":150},
A6: create_time | B6: datetime | C6: 0 | D6: N | E6: NOT NULL | G6: 记录创建时间 | H6: 记录创建时间 | I6: =A6&" "&B6&"("&C6&") "&E6&" "&F6&"," -> create_time datetime(0) NOT NULL , | J6: ="{""field"":"""&A6&""",""name"":"""&G6&""",""dataType"":"""&B6&"""}," -> {"field":"create_time","name":"记录创建时间","dataType":"datetime"}, | K6: ="{""field"":"""&A6&""",""labelRegexp"":"""&G6&""",""excelRangeType"":""table""}," -> {"field":"create_time","labelRegexp":"记录创建时间","excelRangeType":"table"}, | L6: ="{""field"":"""&A6&""",""width"":150}," -> {"field":"create_time","width":150},
A7: create_user | B7: varchar | C7: 25 | D7: N | E7: NOT NULL | G7: 记录创建人 | H7: 记录创建人 | I7: =A7&" "&B7&"("&C7&") "&E7&" "&F7&"," -> create_user varchar(25) NOT NULL , | J7: ="{""field"":"""&A7&""",""name"":"""&G7&""",""dataType"":"""&B7&"""}," -> {"field":"create_user","name":"记录创建人","dataType":"varchar"}, | K7: ="{""field"":"""&A7&""",""labelRegexp"":"""&G7&""",""excelRangeType"":""table""}," -> {"field":"create_user","labelRegexp":"记录创建人","excelRangeType":"table"}, | L7: ="{""field"":"""&A7&""",""width"":150}," -> {"field":"create_user","width":150},
A8: update_time | B8: datetime | C8: 0 | D8: N | E8: NOT NULL | G8: 记录更新时间 | H8: 记录更新时间 | I8: =A8&" "&B8&"("&C8&") "&E8&" "&F8&"," -> update_time datetime(0) NOT NULL , | J8: ="{""field"":"""&A8&""",""name"":"""&G8&""",""dataType"":"""&B8&"""}," -> {"field":"update_time","name":"记录更新时间","dataType":"datetime"}, | K8: ="{""field"":"""&A8&""",""labelRegexp"":"""&G8&""",""excelRangeType"":""table""}," -> {"field":"update_time","labelRegexp":"记录更新时间","excelRangeType":"table"}, | L8: ="{""field"":"""&A8&""",""width"":150}," -> {"field":"update_time","width":150},
A9: update_user | B9: varchar | C9: 25 | D9: N | E9: NOT NULL | G9: 记录更新人 | H9: 记录更新人 | I9: =A9&" "&B9&"("&C9&") "&E9&" "&F9&"," -> update_user varchar(25) NOT NULL , | J9: ="{""field"":"""&A9&""",""name"":"""&G9&""",""dataType"":"""&B9&"""}," -> {"field":"update_user","name":"记录更新人","dataType":"varchar"}, | K9: ="{""field"":"""&A9&""",""labelRegexp"":"""&G9&""",""excelRangeType"":""table""}," -> {"field":"update_user","labelRegexp":"记录更新人","excelRangeType":"table"}, | L9: ="{""field"":"""&A9&""",""width"":150}," -> {"field":"update_user","width":150},
A10: version | B10: int | C10: 11 | D10: N | E10: NOT NULL | F10: DEFAULT 0 | G10: 数据版本号 | H10: 数据版本号 | I10: =A10&" "&B10&"("&C10&") "&E10&" "&F10&"," -> version int(11) NOT NULL DEFAULT 0, | J10: ="{""field"":"""&A10&""",""name"":"""&G10&""",""dataType"":"""&B10&"""}," -> {"field":"version","name":"数据版本号","dataType":"int"}, | K10: ="{""field"":"""&A10&""",""labelRegexp"":"""&G10&""",""excelRangeType"":""table""}," -> {"field":"version","labelRegexp":"数据版本号","excelRangeType":"table"}, | L10: ="{""field"":"""&A10&""",""width"":150}," -> {"field":"version","width":150},
I11: ="PRIMARY KEY (`id`) USING BTREE)" -> PRIMARY KEY (`id`) USING BTREE)

Sheet sl_lock
A1: 表名： | B1: sl_lock | C1: 说明： | D1: 智能锁信息表 | F1: 版本 | H1: 1 | I1: ="create table "&B1&" (" -> create table sl_lock ( | N1: 目录
A2: 字段 | B2: 类型 | C2: 长度 | D2: 主键 | E2: 是否为空 | F2: 默认值 | G2: 字段名称 | H2: 说明
A3: id | B3: varchar | C3: 20 | D3: Y | E3: NOT NULL | G3: 编号 | H3: 锁编号 | I3: =A3&" "&B3&"("&C3&") "&E3&" "&F3&"," -> id varchar(20) NOT NULL , | J3: ="{""field"":"""&A3&""",""name"":"""&G3&""",""dataType"":"""&B3&"""}," -> {"field":"id","name":"编号","dataType":"varchar"}, | K3: ="{""field"":"""&A3&""",""labelRegexp"":"""&G3&""",""excelRangeType"":""table""}," -> {"field":"id","labelRegexp":"编号","excelRangeType":"table"}, | L3: ="{""field"":"""&A3&""",""width"":150}," -> {"field":"id","width":150},
A4: name | B4: varchar | C4: 20 | D4: N | E4: NOT NULL | G4: 名称 | I4: =A4&" "&B4&"("&C4&") "&E4&" "&F4&"," -> name varchar(20) NOT NULL , | J4: ="{""field"":"""&A4&""",""name"":"""&G4&""",""dataType"":"""&B4&"""}," -> {"field":"name","name":"名称","dataType":"varchar"}, | K4: ="{""field"":"""&A4&""",""labelRegexp"":"""&G4&""",""excelRangeType"":""table""}," -> {"field":"name","labelRegexp":"名称","excelRangeType":"table"}, | L4: ="{""field"":"""&A4&""",""width"":150}," -> {"field":"name","width":150},
A5: room | B5: varchar | C5: 20 | D5: N | E5: NULL | G5: 机房 | H5: 机房表外键 | I5: =A5&" "&B5&"("&C5&") "&E5&" "&F5&"," -> room varchar(20) NULL , | J5: ="{""field"":"""&A5&""",""name"":"""&G5&""",""dataType"":"""&B5&"""}," -> {"field":"room","name":"机房","dataType":"varchar"}, | L5: ="{""field"":"""&A5&""",""width"":150}," -> {"field":"room","width":150},
A6: area_type | B6: varchar | C6: 5 | D6: N | E6: NULL | G6: 区域类型 | H6: 区域类性字典表外键 | I6: =A6&" "&B6&"("&C6&") "&E6&" "&F6&"," -> area_type varchar(5) NULL , | J6: ="{""field"":"""&A6&""",""name"":"""&G6&""",""dataType"":"""&B6&"""}," -> {"field":"area_type","name":"区域类型","dataType":"varchar"}, | K6: ="{""field"":"""&A6&""",""labelRegexp"":"""&G6&""",""excelRangeType"":""table""}," -> {"field":"area_type","labelRegexp":"区域类型","excelRangeType":"table"}, | L6: ="{""field"":"""&A6&""",""width"":150}," -> {"field":"area_type","width":150},
A7: rack | B7: varchar | C7: 255 | D7: N | E7: NULL | G7: 机柜 | H7: 可填写机柜编号 | I7: =A7&" "&B7&"("&C7&") "&E7&" "&F7&"," -> rack varchar(255) NULL , | J7: ="{""field"":"""&A7&""",""name"":"""&G7&""",""dataType"":"""&B7&"""}," -> {"field":"rack","name":"机柜","dataType":"varchar"}, | L7: ="{""field"":"""&A7&""",""width"":150}," -> {"field":"rack","width":150},
A8: master_hub | B8: varchar | C8: 20 | D8: N | E8: NOT NULL | G8: 主网关 | I8: =A8&" "&B8&"("&C8&") "&E8&" "&F8&"," -> master_hub varchar(20) NOT NULL , | J8: ="{""field"":"""&A8&""",""name"":"""&G8&""",""dataType"":"""&B8&"""}," -> {"field":"master_hub","name":"主网关","dataType":"varchar"}, | L8: ="{""field"":"""&A8&""",""width"":150}," -> {"field":"master_hub","width":150},
A9: slaver_hub | B9: varchar | C9: 20 | D9: N | E9: NOT NULL | G9: 备份网关 | I9: =A9&" "&B9&"("&C9&") "&E9&" "&F9&"," -> slaver_hub varchar(20) NOT NULL , | J9: ="{""field"":"""&A9&""",""name"":"""&G9&""",""dataType"":"""&B9&"""}," -> {"field":"slaver_hub","name":"备份网关","dataType":"varchar"}, | L9: ="{""field"":"""&A9&""",""width"":150}," -> {"field":"slaver_hub","width":150},
A10: remark | B10: varchar | C10: 255 | D10: N | E10: NULL | G10: 备注 | I10: =A10&" "&B10&"("&C10&") "&E10&" "&F10&"," -> remark varchar(255) NULL , | J10: ="{""field"":"""&A10&""",""name"":"""&G10&""",""dataType"":"""&B10&"""}," -> {"field":"remark","name":"备注","dataType":"varchar"}, | L10: ="{""field"":"""&A10&""",""width"":150}," -> {"field":"remark","width":150},
A11: create_time | B11: datetime | C11: 0 | D11: N | E11: NOT NULL | G11: 记录创建时间 | H11: 记录创建时间 | I11: =A11&" "&B11&"("&C11&") "&E11&" "&F11&"," -> create_time datetime(0) NOT NULL , | J11: ="{""field"":"""&A11&""",""name"":"""&G11&""",""dataType"":"""&B11&"""}," -> {"field":"create_time","name":"记录创建时间","dataType":"datetime"}, | K11: ="{""field"":"""&A11&""",""labelRegexp"":"""&G11&""",""excelRangeType"":""table""}," -> {"field":"create_time","labelRegexp":"记录创建时间","excelRangeType":"table"}, | L11: ="{""field"":"""&A11&""",""width"":150}," -> {"field":"create_time","width":150},
A12: create_user | B12: varchar | C12: 25 | D12: N | E12: NOT NULL | G12: 记录创建人 | H12: 记录创建人 | I12: =A12&" "&B12&"("&C12&") "&E12&" "&F12&"," -> create_user varchar(25) NOT NULL , | J12: ="{""field"":"""&A12&""",""name"":"""&G12&""",""dataType"":"""&B12&"""}," -> {"field":"create_user","name":"记录创建人","dataType":"varchar"}, | K12: ="{""field"":"""&A12&""",""labelRegexp"":"""&G12&""",""excelRangeType"":""table""}," -> {"field":"create_user","labelRegexp":"记录创建人","excelRangeType":"table"}, | L12: ="{""field"":"""&A12&""",""width"":150}," -> {"field":"create_user","width":150},
A13: update_time | B13: datetime | C13: 0 | D13: N | E13: NOT NULL | G13: 记录更新时间 | H13: 记录更新时间 | I13: =A13&" "&B13&"("&C13&") "&E13&" "&F13&"," -> update_time datetime(0) NOT NULL , | J13: ="{""field"":"""&A13&""",""name"":"""&G13&""",""dataType"":"""&B13&"""}," -> {"field":"update_time","name":"记录更新时间","dataType":"datetime"}, | K13: ="{""field"":"""&A13&""",""labelRegexp"":"""&G13&""",""excelRangeType"":""table""}," -> {"field":"update_time","labelRegexp":"记录更新时间","excelRangeType":"table"}, | L13: ="{""field"":"""&A13&""",""width"":150}," -> {"field":"update_time","width":150},
